Workbook
Name \p: #N/A
Name ___6: #REF!
Name ___8: #REF!
Name ___BTM150: #REF!
Name ___BTM200: #REF!
Name ___BTM50: #REF!
Name ___C: #REF!
Name ___CON1: #REF!
Name ___CON2: #REF!
Name ___EXC1: #REF!
Name ___EXC2: #REF!
Name ___hom2: #REF!
Name ___msl100: #REF!
Name ___msl200: #REF!
Name ___msl250: #REF!
Name ___msl300: #REF!
Name ___msl400: #REF!
Name ___msl800: #REF!
Name ___mui100: #REF!
Name ___mui105: #REF!
Name ___mui108: #REF!
Name ___mui130: #REF!
Name ___mui140: #REF!
Name ___mui160: #REF!
Name ___mui180: #REF!
Name ___mui250: #REF!
Name ___mui271: #REF!
Name ___mui320: #REF!
Name ___mui45: #REF!
Name ___mui50: #REF!
Name ___mui54: #REF!
Name ___mui65: #REF!
Name ___mui75: #REF!
Name ___mui80: #REF!
Name ___NET2: #REF!
Name ___R: #REF!
Name ___sat10: #REF!
Name ___sat12: #REF!
Name ___sat14: #REF!
Name ___sat16: #REF!
Name ___sat20: #REF!
Name ___sat8: #REF!
Name ___sua20: #REF!
Name ___sua30: #REF!
Name ___vbt150: #REF!
Name ___vbt200: #REF!
Name ___vbt210: #REF!
Name ___vbt300: #REF!
Name ___vbt400: #REF!
Name ___vxm100: #REF!
Name ___vxm300: #REF!
Name ___vxm500: #REF!
Name ___vxm75: #REF!
Name __6: #REF!
Name __8: #REF!
Name __BTM150: #REF!
Name __BTM200: #REF!
Name __BTM50: #REF!
Name __C: #REF!
Name __CON1: #REF!

Sheet Cover
C1: CONSOLIDATED FINANCIAL STATEMENTS FOR PAST FIVE QUARTERS - BHARTI AIRTEL LIMITED
C2: [AS PER INDIAN ACCOUNTING STANDARDS (Ind-AS)]
C6: Schedule | E6: INDEX
C8: Financial Indicators
C10: 1 | E10: Consolidated Statements of Operations as per Indian Accounting Standards (Ind-AS)
C12: 2 | E12: Consolidated Balance Sheet as per Indian Accounting Standards (Ind-AS)
C14: 3 | E14: Consolidated Statement of Cash Flows as per Indian Accounting Standards (Ind-AS)
C16: 4 | E16: Consolidated Summarised Statement of Operations (net of inter segment eliminations)
C18: 5 | E18: Schedules to Financial Statements
C21: Operational Indicators
C23: 6 | E23: Operational Performance

Sheet Trends file-1
A1: INDEX | B1: CONSOLIDATED FINANCIAL STATEMENTS - BHARTI AIRTEL LIMITED
A3: 1 | B3: Consolidated Statement of Operations as per Indian Accounting Standards (Ind-AS)
A5: =A3+0.1 -> 1.1 | B5: Consolidated Summarized Statement of Income Net of Inter Segment Eliminations
G6: Amount in Rs Mn, except ratios
B7: Particulars | C7: Quarter Ended
C8: 44651 | D8: 44561 | E8: 44469 | F8: 44377 | G8: 44286
B10: Income
B11: Revenue | C11: 315003 | D11: 298666 | E11: 283264 | F11: 268536 | G11: 257473
B12: Other income | C12: 186 | D12: 1971 | E12: 1088 | F12: 2098 | G12: 839.3
B13: Finance Income
B14: Total | C14: 315189 | D14: 300637 | E14: 284352 | F14: 270634 | G14: 258312.3
B16: Expenses
B17: Network operating expenses | C17: 65458 | D17: 64986 | E17: 61788 | F17: 57973 | G17: 59179
B18: Access Charges | C18: 17505 | D18: 17232 | E18: 16708 | F18: 16166 | G18: 15649
B19: License fee / spectrum charges (revenue share) | C19: 30089 | D19: 27298 | E19: 26794 | F19: 26455 | G19: 25011.905
C20: 0 | D20: 0 | E20: 0 | F20: 0 | G20: 0
B21: Employee benefits | C21: 11642 | D21: 11336 | E21: 11010 | F21: 10345 | G21: 9989
B22: Sales and marketing expenses | C22: 15327 | D22: 14425 | E22: 12670 | F22: 10613 | G22: 11484
B23: Other expenses | C23: 14579 | D23: 16361 | E23: 16189 | F23: 17181 | G23: 12840.658
B25: Total | C25: 154600 | D25: 151638 | E25: 145159 | F25: 138733 | G25: 134153.56
B28: Profit from operating activites before depreciation, amortization and exceptional items | C28: 160589 | D28: 148999 | E28: 139193 | F28: 131901 | G28: 124157.74
B31: Depreciation and amortisation | C31: 85826 | D31: 85472 | E31: 82472 | F31: 77137 | G31: 75019.15
B32: Finance costs | C32: 40593 | D32: 43671 | E32: 39641 | F32: 42257 | G32: 38606
B33: Finance income | C33: 0 | D33: 0 | E33: 0 | F33: 0 | G33: 0
B34: Finance Income | C34: 0 | D34: 0 | E34: 0 | F34: 0 | G34: 0
B35: Non-operating income / expenses, (net) | C35: 0 | D35: 0 | E35: 0 | F35: 0 | G35: 0
B36: Share of results of joint ventures and associates | C36: -7136 | D36: -6161 | E36: -5988 | F36: -4947 | G36: -5274
B37: Other Expenses
B39: Profit before exceptional items and tax | C39: 41306 | D39: 26017 | E39: 23068 | F39: 17454 | G39: 15806.587
B42: Exceptional items | C42: -9062 | D42: -398 | E42: -7221 | F42: -305 | G42: -4404
B45: Profit before tax | C45: 50368 | D45: 26415 | E45: 30289 | F45: 17759 | G45: 20210.587
B48: Tax expense
B49: Current tax | C49: 7765 | D49: 7922 | E49: 7370 | F49: 7274 | G49: 6458
B50: Deferred tax | C50: 5453 | D50: 1986 | E50: 2938 | F50: 1071 | G50: -1357
B53: Profit for the period | C53: 37150 | D53: 16507 | E53: 19981 | F53: 9414 | G53: 15109.587
B56: Profit / (loss) from discontinued operation before tax | C56: 0 | D56: 0 | E56: 0 | F56: 0 | G56: 0
B57: Tax expense / (credit) of discontinued operation | C57: 0 | D57: 0 | E57: 0 | F57: 0 | G57: 0
B58: Profit for the period from discontinued operations | C58: 0 | D58: 0 | E58: 0 | F58: 0 | G58: 0
B60: Profit / (Loss) for the period | C60: 37150 | D60: 16507 | E60: 19981 | F60: 9414 | G60: 15109.587
B64: Consolidated Statement of Comprehensive Income
...

Sheet Trends file-2 
A1: INDEX | B1: CONSOLIDATED FINANCIAL STATEMENTS - BHARTI AIRTEL LIMITED
A3: 2 | B3: Consolidated Summarized Balance Sheet (As per Ind AS)
G6: Amount in Rs Mn
B7: Particulars | C7: As at | D7: As at | E7: As at | F7: As at | G7: As at
C8: ='Trends file-1'!C8 -> 44651 | D8: ='Trends file-1'!D8 -> 44561 | E8: ='Trends file-1'!E8 -> 44469 | F8: ='Trends file-1'!F8 -> 44377 | G8: ='Trends file-1'!G8 -> 44286
B9: Assets
B11: Non-current assets
B12: Property, plant and equipment (Incl CWIP) | C12: 1270397 | D12: 1259219 | E12: 1246145 | F12: 1213714 | G12: 1189828
B15: Intangible assets | C15: 1229983 | D15: 1242858 | E15: 1261001 | F15: 1261199 | G15: 1102233
B16: Right-of-use assets | C16: 0 | D16: 0 | E16: 0 | F16: 0 | G16: 0
B17: Investment in joint ventures and associates | C17: 284268 | D17: 252558 | E17: 245656 | F17: 239222 | G17: 234346
B18: Financial Assets
B19: - Investments | C19: 609 | D19: 471 | E19: 469 | F19: 471 | G19: 377
B23: - Others | C23: 22733 | D23: 22846 | E23: 23405 | F23: 23422 | G23: 23402
B25: Income & Deferred tax assets (net) | C25: 216729 | D25: 222564 | E25: 221408 | F25: 222493 | G25: 222103
B26: Other non-current assets | C26: 91562 | D26: 84316 | E26: 79533 | F26: 82147 | G26: 140460
C27: 3116281 | D27: 3084832 | E27: 3077617 | F27: 3042668 | G27: 2912749
B29: Current assets
B31: Financial Assets
B32: - Investments | C32: 8614 | D32: 4440 | E32: 70632 | F32: 1970 | G32: 40781
B34: - Trade receivables | C34: 40562 | D34: 49846 | E34: 50350 | F34: 47707 | G34: 36377
B35: - Cash and bank balance | C35: 60959 | D35: 73015 | E35: 61707 | F35: 84917 | G35: 80859
B36: - Bank deposits | C36: 73984 | D36: 68564 | E36: 58075 | F36: 42444 | G36: 53802
B38: - Receivable from sale of tower assets | C38: 0 | D38: 0 | E38: 0 | F38: 0 | G38: 0
B39: - Others | C39: 215258 | D39: 208794 | E39: 201740 | F39: 198115 | G39: 192448
B40: Current tax assets | C40: 0 | D40: 0 | E40: 0 | F40: 0 | G40: 0
B41: Other current assets | C41: 120902 | D41: 132449 | E41: 138239 | F41: 140772 | G41: 143262
C46: 520279 | D46: 537108 | E46: 580743 | F46: 515925 | G46: 547529
B49: Total Assets | C49: 3636560 | D49: 3621940 | E49: 3658360 | F49: 3558593 | G49: 3460278
B55: Equity and liabilities
B56: Equity
B60: Equity attributable to owners of the Parent | C60: 665543 | D60: 658630 | E60: 601874 | F60: 592034 | G60: 589527
B61: Non-controlling interests ('NCI') | C61: 253807 | D61: 229006 | E61: 233642 | F61: 228909 | G61: 222739
C62: 919350 | D62: 887636 | E62: 835516 | F62: 820943 | G62: 812266
B64: Non-current liabilities
B65: Financial Liabilities
B66: - Borrowings | C66: 1425912 | D66: 1449385 | E66: 1562933 | F66: 1493080 | G66: 1356689
B68: - Others | C68: 90290 | D68: 141397 | E68: 132013 | F68: 93167 | G68: 122393
B70: Lease liabilities | C70: 0 | D70: 0 | E70: 0 | F70: 0 | G70: 0
B71: Deferred tax liabilities (net) | C71: 24488 | D71: 20906 | E71: 19068 | F71: 16709 | G71: 16107
...

Sheet Trends file-3
A1: INDEX | B1: CONSOLIDATED FINANCIAL STATEMENTS - BHARTI AIRTEL LIMITED
A3: 3 | B3: Consolidated Statement of Cash Flows
G6: ='Trends file-2 '!$G$6 -> Amount in Rs Mn
B7: Particulars | C7: Quarter Ended
C8: ='Trends file-1'!C8 -> 44651 | D8: ='Trends file-1'!D8 -> 44561 | E8: ='Trends file-1'!E8 -> 44469 | F8: ='Trends file-1'!F8 -> 44377 | G8: ='Trends file-1'!G8 -> 44286
B9: Cash flows from operating activities
B11: Profit before tax | C11: 50366.798 | D11: 26415.599 | E11: 30288.837 | F11: 17758.731 | G11: 20210.836
B13: Adjustments for -
B14: Depreciation and amortisation | C14: 85825.115 | D14: 85471.92 | E14: 82472.61 | F14: 77136.879 | G14: 75022.563
B15: Finance costs | C15: 40529.289 | D15: 43280.109 | E15: 39384.503 | F15: 42046.813 | G15: 39090.489
B17: Net gain on FVTPL investments | C17: -164.19316 | D17: -520.92414 | E17: -139.65321 | F17: -242.43073 | G17: -207.57086
B18: Interest income | C18: -1026.4862 | D18: -424.32819 | E18: -413.08697 | F18: -343.06079 | G18: -337.84937
B19: Net loss/ (gain) on derivative financial instruments | C19: -423.70255 | D19: 865.89874 | E19: 1357.5506 | F19: -853.11663 | G19: 524.50847
B20: Net fair value gain on financial instruments | C20: 0 | D20: 0 | E20: 0 | F20: 0 | G20: 0
B21: (Gain) / loss on deemed disposal of subsidiary | C21: 0 | D21: 0 | E21: 0 | F21: 0 | G21: 0
B22: Other non-cash items | C22: -10473.727 | D22: -6584.3974 | E22: -12792.489 | F22: -2411.339 | G22: -10394.379
B24: Operating cash flow before changes in working capital | C24: 164633 | D24: 148505 | E24: 140160 | F24: 133093 | G24: 123908
B25: Changes in working capital -
B26: Trade receivables | C26: 8373.1804 | D26: 257.71678 | E26: -2534.0897 | F26: -13227.643 | G26: 10361.824
B27: Trade payables | C27: -22111.701 | D27: 5265.4804 | E27: -13296.817 | F27: 25267.04 | G27: -15779.757
B31: Other assets and liabilities | C31: -8338.3573 | D31: 10000.397 | E31: 6259.469 | F31: -10386.23 | G31: 4858.349
B33: Net cash generated from operations before tax and dividend | C33: 142556 | D33: 164028 | E33: 130588 | F33: 134746 | G33: 123348
B36: Income tax paid | C36: 1298.4733 | D36: -6570.5442 | E36: -3954.7487 | F36: -12525.528 | G36: -3379.9177
B38: Net cash generated from operating activities (a) | C38: 143854 | D38: 157457 | E38: 126633 | F38: 122220 | G38: 119968
B40: Cash flows from investing activities
B42: Net (Purchase) / proceeds from sale of PPE | C42: -50475.615 | D42: -67699.524 | E42: -60888.324 | F42: -71552.376 | G42: -69260.995
B43: Purchase of intangible assets, spectrum- DPL | C43: -38999.46 | D43: -132229.61 | E43: -8080.6512 | F43: -3765.2497 | G43: -78484.754
B44: Net movement in current investments | C44: -10681.491 | D44: 60065.181 | E44: -83058.411 | F44: 54972.163 | G44: -53467.022
B45: Proceeds from Sale of Spectrum | C45: 0 | D45: 0 | E45: 10048 | F45: 0 | G45: 0
B46: Net (Purchase) / Sale of non-current investments | C46: -13.877826 | D46: -0.43191884 | E46: 0.06127117 | F46: -75.061884 | G46: -16.541167
B49: Cash acquired on business combination
B50: Sale of tower assets | C50: 2566.6618 | D50: 3319.6666 | E50: 0 | F50: 0 | G50: 0
B51: Investment in joint venture / associate | C51: -25289 | D51: -919 | E51: 0 | F51: 0 | G51: -51.487661
B52: Loan given to subsidiaries | C52: 0 | D52: 0 | E52: 8 | F52: 0 | G52: 0
B53: Adjustment on account of deemed disposal of subsidiary | C53: 0 | D53: 0 | E53: 0 | F53: 0 | G53: 0
B54: Dividend received | C54: 0 | D54: 0 | E54: 0 | F54: 0 | G54: 20039
B55: Interest received | C55: 2678.3359 | D55: 581.4318 | E55: 401.06621 | F55: 392.03663 | G55: 374.52813
B56: Repayment of Loan given to Joint Venture/Associate | C56: 0 | D56: 0 | E56: 0 | F56: 0 | G56: 0
B58: Net cash (used in) / generated from investing activities (b) | C58: -120214 | D58: -136881 | E58: -141570 | F58: -20028 | G58: -180868
B60: Cash flows from financing activities
...

Sheet Trends file-4
A1: INDEX
A3: 4 | B3: Consolidated Summarised Statement of Operations as per Ind-AS (net of inter segment eliminations)
G4: ='Trends file-1'!$G$6 -> Amount in Rs Mn, except ratios
B5: Particulars | C5: Quarter Ended
C6: ='Trends file-1'!C8 -> 44651 | D6: ='Trends file-1'!D8 -> 44561 | E6: ='Trends file-1'!E8 -> 44469 | F6: ='Trends file-1'!F8 -> 44377 | G6: ='Trends file-1'!G8 -> 44286
B7: Total revenues | C7: 315003 | D7: 298666.37 | E7: 283263.5 | F7: 268536.23 | G7: 257473
B8: Total Revenues - Recasted for IUC | C8: 315003 | D8: 298666.37 | E8: 283263.5 | F8: 268536.23 | G8: 257473
B9: EBITDA | C9: 159984.32 | D9: 149047.21 | E9: 140177.11 | F9: 131894.36 | G9: 125831
B10: EBITDA / Total revenues | C10: 0.50788188 | D10: 0.49904251 | E10: 0.4948647 | F10: 0.4911604 | G10: 0.48871532
B11: EBIT | C11: 73149.268 | D11: 63446.885 | E11: 57563.989 | F11: 54370.636 | G11: 50480
B12: Finance cost (net) | C12: 38980.497 | D12: 43591.55 | E12: 40444.966 | F12: 40818.105 | G12: 38586
B13: Share of results of Joint Ventures / Associates | C13: 7136.2057 | D13: 6160.9404 | E13: 5988.2471 | F13: 4946.6314 | G13: 5274
B14: Profit before Tax | C14: 41305.576 | D14: 26016.875 | E14: 23068.424 | F14: 17454.316 | G14: 15807
B15: Income tax expense | C15: 14002.291 | D15: 9907.5035 | E15: 8491.2632 | F15: 8344.8932 | G15: 6495
B16: Profit after tax (before exceptional items) | C16: 27303.285 | D16: 16109.371 | E16: 14577.161 | F16: 9109.4224 | G16: 9312
B17: Non Controlling Interest | C17: 8700.5524 | D17: 8035.921 | E17: 8640.4019 | F17: 6445.0326 | G17: 6090
B18: Net income (before exceptional items) | C18: 18602.733 | D18: 8073.45 | E18: 5936.7588 | F18: 2664.3898 | G18: 3222
... B26: Cumulative Investments | C26: 4231487.4 | D26: 4179029.5 | E26: 4142438.6 | F26: 4061360 | G26: 3884792.4
B27: *Share of results of Joint Ventures/Associates includes the equity pick up of erstwhile Bharti Infratel Limited (now Indus Towers Limited) for periods represented.
B28: Region and Segment wise summarised statement of operations as per Ind-AS:
A30: 4.1 | B30: India South Asia- Summarised Statement of Operations as per Ind-AS (net of inter segment eliminations)
G31: ='Trends file-1'!$G$6 -> Amount in Rs Mn, except ratios
B32: Particulars | C32: Quarter Ended
C33: =$C$6 -> 44651 | D33: =$D$6 -> 44561 | E33: =$E$6 -> 44469 | F33: =$F$6 -> 44377 | G33: =$G$6 -> 44286
B34: Total revenues | C34: 225895.07 | D34: 210022.66 | E34: 199791.8 | F34: 189167.93 | G34: 184269
B35: Total Revenues - Recasted for IUC | C35: 225895.07 | D35: 210022.66 | E35: 199791.8 | F35: 189167.93 | G35: 184269
B36: Net revenue | C36: 186229.53 | D36: 173346.19 | E36: 164288.8 | F36: 155202.98 | G36: 151830
B37: EBITDA | C37: 114200.69 | D37: 103857.92 | E37: 98434.668 | F37: 92623.442 | G37: 89580
B38: EBITDA / Total revenues | C38: 0.50554754 | D38: 0.49450816 | E38: 0.49268622 | F38: 0.48963608 | G38: 0.48613711
B39: EBIT | C39: 41567.149 | D39: 32508.41 | E39: 29507.536 | F39: 28446.621 | G39: 27152
B40: Profit before Tax | C40: 14015.109 | D40: 6453.5024 | E40: 5135.3168 | F40: -3344.0756 | G40: -1263.4855
B41: Income tax expense | C41: 3856.8158 | D41: 975.5358 | E41: 416.01643 | F41: -791.93146 | G41: 109
B42: Profit after Tax (before exceptional items) | C42: 10158.293 | D42: 5477.9666 | E42: 4719.3004 | F42: -2552.1441 | G42: -1372.4855
B43: Non Controlling Interest | C43: 1644.4954 | D43: 1213.0254 | E43: 1245.073 | F43: 1340.0634 | G43: 984
B44: Net income (before exceptional items) | C44: 8513.798 | D44: 4264.9412 | E44: 3474.2274 | F44: -3892.2075 | G44: -2356.4855
B45: Capex | C45: 43155.147 | D45: 47049.753 | E45: 59407.352 | F45: 58113.085 | G45: 53007.259
... B47: Cumulative Investments | C47: 3538863.4 | D47: 3509004.8 | E47: 3472504.2 | F47: 3402127.8 | G47: 3230503.8
A50: 4.1.1 | B50: India - Summarised Statement of Operations as per Ind-AS (net of inter segment eliminations)
G51: ='Trends file-1'!$G$6 -> Amount in Rs Mn, except ratios
B52: Particulars | C52: Quarter Ended
...

Sheet Trends file-5-SCH
A1: INDEX
A3: 5 | B3: Schedules to Financial Statements
A5: 5.1 | B5: India
A7: 5.1.1 | B7: Operating Expenses
G8: ='Trends file-4'!G4 -> Amount in Rs Mn, except ratios
B9: Particulars | C9: Quarter Ended
C10: ='Trends file-1'!C8 -> 44651 | D10: ='Trends file-1'!D8 -> 44561 | E10: ='Trends file-1'!E8 -> 44469 | F10: ='Trends file-1'!F8 -> 44377 | G10: ='Trends file-1'!G8 -> 44286
B11: Access charges | C11: 11657.386 | D11: 11495.266 | E11: 11129.188 | F11: 10609.737 | G11: 11209
B12: Licence fees, revenue share & spectrum charges | C12: 25567.952 | D12: 22876.571 | E12: 22376.662 | F12: 21345.738 | G12: 19578.735
B13: Network operations costs | C13: 49466.846 | D13: 49610.442 | E13: 46712.779 | F13: 43497.783 | G13: 45437.02
B14: Cost of good sold | C14: 2155.2138 | D14: 2005.6888 | E14: 1719.9582 | F14: 1745.5971 | G14: 1395
B15: Employee costs | C15: 5824.4715 | D15: 4980.3921 | E15: 5785.8416 | F15: 5379.0952 | G15: 5177.8055
B16: Selling, general and adminstration expense | C16: 17829.895 | D16: 14960.861 | E16: 13473.949 | F16: 13999.05 | G16: 12026.009
B17: Operating Expenses | C17: 112501.76 | D17: 105929.22 | E17: 101198.38 | F17: 96577.001 | G17: 94823.57
A19: 5.1.2 | B19: Depreciation and Amortisation
G20: =G8 -> Amount in Rs Mn, except ratios
B21: Particulars | C21: Quarter Ended
C22: ='Trends file-4'!$C$6 -> 44651 | D22: ='Trends file-4'!$D$6 -> 44561 | E22: ='Trends file-4'!$E$6 -> 44469 | F22: ='Trends file-4'!$F$6 -> 44377 | G22: ='Trends file-4'!$G$6 -> 44286
B23: Depreciation | C23: 54340 | D23: 53638.249 | E23: 51617.815 | F23: 47935.82 | G23: 46819.096
B24: Amortization | C24: 16919.017 | D24: 17129.841 | E24: 16744.719 | F24: 15457.042 | G24: 14948.176
B25: Depreciation and Amortisation | C25: 71259.016 | D25: 70768.09 | E25: 68362.534 | F25: 63392.862 | G25: 61767.272
A27: 5.1.3 | B27: Income Tax
G28: =G20 -> Amount in Rs Mn, except ratios
B29: Particulars | C29: Quarter Ended
C30: ='Trends file-4'!$C$6 -> 44651 | D30: ='Trends file-4'!$D$6 -> 44561 | E30: ='Trends file-4'!$E$6 -> 44469 | F30: ='Trends file-4'!$F$6 -> 44377 | G30: ='Trends file-4'!$G$6 -> 44286
B31: Current tax expense | C31: 1199.5001 | D31: 962.375 | E31: 1176.3455 | F31: 1164.1726 | G31: 843.87883
B32: Deferred tax expense / (income) | C32: 2657.3157 | D32: 13.1608 | E32: -760.32907 | F32: -1956.1041 | G32: -734.77493
B34: Income tax expense | C34: 3856.8158 | D34: 975.5358 | E34: 416.01643 | F34: -791.93146 | G34: 109.1039
A39: 5.2 | B39: South Asia
A41: 5.2.1 | B41: Operating Expenses
G42: =G28 -> Amount in Rs Mn, except ratios
B43: Particulars | C43: Quarter Ended
C44: ='Trends file-4'!$C$6 -> 44651 | D44: ='Trends file-4'!$D$6 -> 44561 | E44: ='Trends file-4'!$E$6 -> 44469 | F44: ='Trends file-4'!$F$6 -> 44377 | G44: ='Trends file-4'!$G$6 -> 44286
B45: Access charges | C45: 161.5317 | D45: 146.89126 | E45: 124.09184 | F45: 113.52466 | G45: 110.04947
B46: Licence fees, revenue share & spectrum charges | C46: 168.51904 | D46: 180.24156 | E46: 178.23511 | F46: 176.97672 | G46: 171.45834
B47: Network operations costs | C47: 480.38044 | D47: 452.78784 | E47: 429.66405 | F47: 456.94743 | G47: 372.79312
B48: Cost of good sold | C48: 0.20521351 | D48: 0.56629946 | E48: -1.4772172 | F48: 0.34377621 | G48: 0.2661113
B49: Employee costs | C49: 101.56029 | D49: 102.48518 | E49: 99.462312 | F49: 102.46365 | G49: 104.93749
B50: Selling, general and adminstration expense | C50: 247.79718 | D50: 301.6527 | E50: 269.21185 | F50: 212.01563 | G50: 344.45611
B51: Operating Expenses | C51: 1159.9939 | D51: 1184.6248 | E51: 1099.1879 | F51: 1062.2719 | G51: 1103.9606
...

Sheet Trends file-6-Ops
A1: INDEX | F1: =1000 -> 1000
A3: 6.1 Operational Performance - INDIA
A5: Parameters | B5: Unit | C5: ='Trends file-5-SCH'!C10 -> 44651 | D5: ='Trends file-5-SCH'!D10 -> 44561 | E5: ='Trends file-5-SCH'!E10 -> 44469 | F5: ='Trends file-5-SCH'!F10 -> 44377 | G5: ='Trends file-5-SCH'!G10 -> 44286
A7: Total Customers Base | B7: 000's | C7: 359903.57 | D7: 355872.91 | E7: 354510.56 | F7: 350866.94 | G7: 350304.39
A9: Mobile Services
A10: Customer Base | B10: 000's | C10: 326043.25 | D10: 322917.59 | E10: 323476.47 | F10: 321238.12 | G10: 321373.51
A12: Net Additions | B12: 000's | C12: 3125.661 | D12: -558.875 | E12: 2238.345 | F12: -135.387 | G12: 13425.924
A13: Pre-Paid (as % of total Customer Base) | B13: % | C13: 0.94539226 | D13: 0.94551319 | E13: 0.94659875 | F13: 0.94732225 | G13: 0.9482444
A14: Monthly Churn | B14: % | C14: 0.028139047 | D14: 0.029222073 | E14: 0.030038177 | F14: 0.027981353 | G14: 0.022472763
A16: Average Revenue Per User (ARPU) | B16: Rs | C16: 178.25448 | D16: 162.60633 | E16: 153.43463 | F16: 146.13668 | G16: 145.21147
A17: Average Revenue Per User (ARPU) | B17: US | C17: 2.3714039 | D17: 2.1773866 | E17: 2.0719127 | F17: 1.9905788 | G17: 1.9822062
A18: Average Revenue Per User (ARPU) - Recasted for IUC | B18: Rs | C18: 178.25448 | D18: 162.51054 | E18: 153.43463 | F18: 146.13668 | G18: 145.21147
A19: Revenue per site per month | B19: Rs | C19: 246442.29 | D19: 232009.6 | E19: 224223.77 | F19: 214416.25 | G19: 215408.56
A20: Revenue per site per month - Recasted for IUC | B20: Rs | C20: 246442.29 | D20: 232009.6 | E20: 224223.77 | F20: 214416.25 | G20: 215408.56
A26: Voice
A27: Minutes on the network | B27: Mn | C27: 1051115.7 | D27: 1029802.1 | E27: 1020414.6 | F27: 1002263.3 | G27: 996793.1
A29: Voice Usage per customer | B29: min | C29: 1082.7037 | D29: 1060.6729 | E29: 1052.8949 | F29: 1043.988 | G29: 1052.798
A40: Data
A41: Data Customer Base | B41: 000's | C41: 208448.43 | D41: 202950.64 | E41: 200027.1 | F41: 192934.93 | G41: 188635.41
A42: Of which 4G data customers | B42: 000's | C42: 200786.28 | D42: 195540.68 | E42: 192538.56 | F42: 184426.83 | G42: 179292.94
A43: As % of customer base | B43: % | C43: 0.63932753 | D43: 0.6284905 | E43: 0.61836678 | F43: 0.60059787 | G43: 0.58696626
A44: Total MBs on the network | B44: Mn MBs | C44: 11849334 | D44: 11311780 | E44: 11270769 | F44: 10771051 | G44: 9207030.3
A46: Data Usage per customer | B46: MBs | C46: 19228.494 | D46: 18726.723 | E46: 19065.72 | F46: 18931.596 | G46: 16839.763
A49: Homes Services
A50: Homes Customers | B50: 000's | C50: 4482.8513 | D50: 4160.1123 | E50: 3819.0793 | F50: 3351.7103 | G50: 3066.5153
A53: Net Additions | B53: 000's | C53: 322.739 | D53: 341.033 | E53: 467.369 | F53: 285.195 | G53: 273.52
A54: Average Revenue Per User (ARPU) | B54: Rs | C54: 650.21634 | D54: 656.98566 | E54: 661.12382 | F54: 681.35662 | G54: 684.06609
A55: Average Revenue Per User (ARPU) | B55: US | C55: 8.6501364 | D55: 8.7973932 | E55: 8.9275206 | F55: 9.2809965 | G55: 9.3378301
A58: Digital TV Services
A59: Digital TV Customers | B59: 000's | C59: 17558.239 | D59: 18066.137 | E59: 17987.347 | F59: 17998.514 | G59: 17716.127
A60: Net additions | B60: 000's | C60: -507.898 | D60: 78.79 | E60: -11.166777 | F60: 282.387 | G60: -156.13981
A61: Average Revenue Per User (ARPU) * | B61: Rs | C61: 141.73459 | D61: 145.98992 | E61: 147.79085 | F61: 150.73214 | G61: 143.83368
A62: Average Revenue Per User (ARPU) | B62: US | C62: 1.8855625 | D62: 1.9548839 | E62: 1.9957016 | F62: 2.0531751 | G62: 1.9633987
A63: Monthly Churn | B63: % | C63: 0.021251353 | D63: 0.020534765 | E63: 0.02165758 | F63: 0.013584787 | G63: 0.02158276
A82: Parameters | B82: Unit | C82: =C5 -> 44651 | D82: =D5 -> 44561 | E82: =E5 -> 44469 | F82: =F5 -> 44377 | G82: =G5 -> 44286
A83: Mobile Services
A84: Census Towns | B84: Nos | C84: 7913 | D84: 7913 | E84: 7913 | F84: 7913 | G84: 7907
A85: Non-Census Towns & Villages | B85: Nos | C85: 795126 | D85: 794484 | E85: 793591 | F85: 793350 | G85: 792827
A86: Population Coverage | B86: % | C86: 0.95655404 | D86: 0.9563317 | E86: 0.95562185 | F86: 0.95526101 | G86: 0.95476298
A87: Optic Fibre Network | B87: R kms | C87: 355079 | D87: 346243 | E87: 340690 | F87: 332542 | G87: 324825
...
